----Start Listen at port 12345 ----
Traceback (most recent call last):
  File "server.py", line 190, in <module>
    fd, addr = sock.accept()
  File "/usr/lib/python3.8/socket.py", line 292, in accept
    fd, addr = self._accept()
KeyboardInterrupt
Process ForkPoolWorker-2:
Traceback (most recent call last):
  File "/usr/lib/python3.8/multiprocessing/process.py", line 315, in _bootstrap
    self.run()
  File "/usr/lib/python3.8/multiprocessing/process.py", line 108, in run
    self._target(*self._args, **self._kwargs)
  File "/usr/lib/python3.8/multiprocessing/pool.py", line 114, in worker
    task = get()
  File "/usr/lib/python3.8/multiprocessing/queues.py", line 355, in get
    with self._rlock:
  File "/usr/lib/python3.8/multiprocessing/synchronize.py", line 95, in __enter__
    return self._semlock.__enter__()
KeyboardInterrupt
Process ForkPoolWorker-4:
Traceback (most recent call last):
  File "/usr/lib/python3.8/multiprocessing/process.py", line 315, in _bootstrap
    self.run()
  File "/usr/lib/python3.8/multiprocessing/process.py", line 108, in run
    self._target(*self._args, **self._kwargs)
  File "/usr/lib/python3.8/multiprocessing/pool.py", line 114, in worker
    task = get()
  File "/usr/lib/python3.8/multiprocessing/queues.py", line 355, in get
    with self._rlock:
  File "/usr/lib/python3.8/multiprocessing/synchronize.py", line 95, in __enter__
    return self._semlock.__enter__()
KeyboardInterrupt
Process ForkPoolWorker-3:
Traceback (most recent call last):
  File "/usr/lib/python3.8/multiprocessing/process.py", line 315, in _bootstrap
    self.run()
  File "/usr/lib/python3.8/multiprocessing/process.py", line 108, in run
    self._target(*self._args, **self._kwargs)
  File "/usr/lib/python3.8/multiprocessing/pool.py", line 114, in worker
    task = get()
  File "/usr/lib/python3.8/multiprocessing/queues.py", line 355, in get
    with self._rlock:
  File "/usr/lib/python3.8/multiprocessing/synchronize.py", line 95, in __enter__
    return self._semlock.__enter__()
KeyboardInterrupt
----Start Listen at port 12345 ----
Traceback (most recent call last):
  File "server.py", line 182, in <module>
    sock.bind((socket.gethostname(), PORT))
OSError: [Errno 98] Address already in use
Traceback (most recent call last):
  File "server.py", line 182, in <module>
    sock.bind((socket.gethostname(), PORT))
OSError: [Errno 98] Address already in use
Traceback (most recent call last):
  File "server.py", line 182, in <module>
    sock.bind((socket.gethostname(), PORT))
OSError: [Errno 98] Address already in use
Traceback (most recent call last):
  File "server.py", line 182, in <module>
    sock.bind((socket.gethostname(), PORT))
OSError: [Errno 98] Address already in use
Traceback (most recent call last):
  File "server.py", line 182, in <module>
    sock.bind((socket.gethostname(), PORT))
OSError: [Errno 98] Address already in use
Traceback (most recent call last):
  File "server.py", line 182, in <module>
    sock.bind((socket.gethostname(), PORT))
OSError: [Errno 98] Address already in use
Traceback (most recent call last):
  File "server.py", line 182, in <module>
    sock.bind((socket.gethostname(), PORT))
OSError: [Errno 98] Address already in use
Traceback (most recent call last):
  File "server.py", line 182, in <module>
    sock.bind((socket.gethostname(), PORT))
OSError: [Errno 98] Address already in use
Traceback (most recent call last):
  File "server.py", line 182, in <module>
    sock.bind((socket.gethostname(), PORT))
OSError: [Errno 98] Address already in use
Traceback (most recent call last):
  File "server.py", line 182, in <module>
    sock.bind((socket.gethostname(), PORT))
OSError: [Errno 98] Address already in use
Traceback (most recent call last):
  File "server.py", line 182, in <module>
    sock.bind((socket.gethostname(), PORT))
OSError: [Errno 98] Address already in use
Traceback (most recent call last):
  File "server.py", line 182, in <module>
    sock.bind((socket.gethostname(), PORT))
OSError: [Errno 98] Address already in use
Traceback (most recent call last):
  File "server.py", line 182, in <module>
    sock.bind((socket.gethostname(), PORT))
OSError: [Errno 98] Address already in use
Traceback (most recent call last):
  File "server.py", line 182, in <module>
    sock.bind((socket.gethostname(), PORT))
OSError: [Errno 98] Address already in use
Traceback (most recent call last):
  File "server.py", line 182, in <module>
    sock.bind((socket.gethostname(), PORT))
OSError: [Errno 98] Address already in use
Traceback (most recent call last):
  File "server.py", line 182, in <module>
    sock.bind((socket.gethostname(), PORT))
OSError: [Errno 98] Address already in use
Traceback (most recent call last):
  File "server.py", line 182, in <module>
    sock.bind((socket.gethostname(), PORT))
OSError: [Errno 98] Address already in use
Traceback (most recent call last):
  File "server.py", line 182, in <module>
    sock.bind((socket.gethostname(), PORT))
OSError: [Errno 98] Address already in use
Traceback (most recent call last):
  File "server.py", line 182, in <module>
    sock.bind((socket.gethostname(), PORT))
OSError: [Errno 98] Address already in use
Traceback (most recent call last):
  File "server.py", line 182, in <module>
    sock.bind((socket.gethostname(), PORT))
OSError: [Errno 98] Address already in use
Traceback (most recent call last):
  File "server.py", line 182, in <module>
    sock.bind((socket.gethostname(), PORT))
OSError: [Errno 98] Address already in use
Traceback (most recent call last):
  File "server.py", line 182, in <module>
    sock.bind((socket.gethostname(), PORT))
OSError: [Errno 98] Address already in use
Traceback (most recent call last):
  File "server.py", line 182, in <module>
    sock.bind((socket.gethostname(), PORT))
OSError: [Errno 98] Address already in use
Traceback (most recent call last):
  File "server.py", line 182, in <module>
    sock.bind((socket.gethostname(), PORT))
OSError: [Errno 98] Address already in use
Traceback (most recent call last):
  File "server.py", line 182, in <module>
    sock.bind((socket.gethostname(), PORT))
OSError: [Errno 98] Address already in use
Traceback (most recent call last):
  File "server.py", line 182, in <module>
    sock.bind((socket.gethostname(), PORT))
OSError: [Errno 98] Address already in use
Traceback (most recent call last):
  File "server.py", line 182, in <module>
    sock.bind((socket.gethostname(), PORT))
OSError: [Errno 98] Address already in use
Traceback (most recent call last):
  File "server.py", line 182, in <module>
    sock.bind((socket.gethostname(), PORT))
OSError: [Errno 98] Address already in use
Traceback (most recent call last):
  File "server.py", line 182, in <module>
    sock.bind((socket.gethostname(), PORT))
OSError: [Errno 98] Address already in use
Traceback (most recent call last):
  File "server.py", line 182, in <module>
    sock.bind((socket.gethostname(), PORT))
OSError: [Errno 98] Address already in use
Traceback (most recent call last):
  File "server.py", line 182, in <module>
    sock.bind((socket.gethostname(), PORT))
OSError: [Errno 98] Address already in use
Traceback (most recent call last):
  File "server.py", line 182, in <module>
    sock.bind((socket.gethostname(), PORT))
OSError: [Errno 98] Address already in use
Traceback (most recent call last):
  File "server.py", line 182, in <module>
    sock.bind((socket.gethostname(), PORT))
OSError: [Errno 98] Address already in use
Traceback (most recent call last):
  File "server.py", line 182, in <module>
    sock.bind((socket.gethostname(), PORT))
OSError: [Errno 98] Address already in use
Traceback (most recent call last):
  File "server.py", line 182, in <module>
    sock.bind((socket.gethostname(), PORT))
OSError: [Errno 98] Address already in use
Traceback (most recent call last):
  File "server.py", line 182, in <module>
    sock.bind((socket.gethostname(), PORT))
OSError: [Errno 98] Address already in use
Traceback (most recent call last):
  File "server.py", line 182, in <module>
    sock.bind((socket.gethostname(), PORT))
OSError: [Errno 98] Address already in use
Traceback (most recent call last):
  File "server.py", line 182, in <module>
    sock.bind((socket.gethostname(), PORT))
OSError: [Errno 98] Address already in use
Traceback (most recent call last):
  File "server.py", line 182, in <module>
    sock.bind((socket.gethostname(), PORT))
OSError: [Errno 98] Address already in use
Traceback (most recent call last):
  File "server.py", line 182, in <module>
    sock.bind((socket.gethostname(), PORT))
OSError: [Errno 98] Address already in use
Traceback (most recent call last):
  File "server.py", line 182, in <module>
    sock.bind((socket.gethostname(), PORT))
OSError: [Errno 98] Address already in use
Traceback (most recent call last):
  File "server.py", line 182, in <module>
    sock.bind((socket.gethostname(), PORT))
OSError: [Errno 98] Address already in use
Traceback (most recent call last):
  File "server.py", line 182, in <module>
    sock.bind((socket.gethostname(), PORT))
OSError: [Errno 98] Address already in use
Traceback (most recent call last):
  File "server.py", line 182, in <module>
    sock.bind((socket.gethostname(), PORT))
OSError: [Errno 98] Address already in use
Traceback (most recent call last):
  File "server.py", line 182, in <module>
    sock.bind((socket.gethostname(), PORT))
OSError: [Errno 98] Address already in use
Traceback (most recent call last):
  File "server.py", line 182, in <module>
    sock.bind((socket.gethostname(), PORT))
OSError: [Errno 98] Address already in use
Traceback (most recent call last):
  File "server.py", line 182, in <module>
    sock.bind((socket.gethostname(), PORT))
OSError: [Errno 98] Address already in use
Traceback (most recent call last):
  File "server.py", line 182, in <module>
    sock.bind((socket.gethostname(), PORT))
OSError: [Errno 98] Address already in use
Traceback (most recent call last):
  File "server.py", line 182, in <module>
    sock.bind((socket.gethostname(), PORT))
OSError: [Errno 98] Address already in use
Traceback (most recent call last):
  File "server.py", line 182, in <module>
    sock.bind((socket.gethostname(), PORT))
OSError: [Errno 98] Address already in use
Traceback (most recent call last):
  File "server.py", line 182, in <module>
    sock.bind((socket.gethostname(), PORT))
OSError: [Errno 98] Address already in use
Traceback (most recent call last):
  File "server.py", line 182, in <module>
    sock.bind((socket.gethostname(), PORT))
OSError: [Errno 98] Address already in use
Traceback (most recent call last):
  File "server.py", line 182, in <module>
    sock.bind((socket.gethostname(), PORT))
OSError: [Errno 98] Address already in use
Traceback (most recent call last):
  File "server.py", line 182, in <module>
    sock.bind((socket.gethostname(), PORT))
OSError: [Errno 98] Address already in use
Traceback (most recent call last):
  File "server.py", line 182, in <module>
    sock.bind((socket.gethostname(), PORT))
OSError: [Errno 98] Address already in use
Traceback (most recent call last):
  File "server.py", line 182, in <module>
    sock.bind((socket.gethostname(), PORT))
OSError: [Errno 98] Address already in use
Traceback (most recent call last):
  File "server.py", line 182, in <module>
    sock.bind((socket.gethostname(), PORT))
OSError: [Errno 98] Address already in use
Traceback (most recent call last):
  File "server.py", line 182, in <module>
    sock.bind((socket.gethostname(), PORT))
OSError: [Errno 98] Address already in use
Traceback (most recent call last):
  File "server.py", line 182, in <module>
    sock.bind((socket.gethostname(), PORT))
OSError: [Errno 98] Address already in use
Traceback (most recent call last):
  File "server.py", line 182, in <module>
    sock.bind((socket.gethostname(), PORT))
OSError: [Errno 98] Address already in use
Traceback (most recent call last):
  File "server.py", line 182, in <module>
    sock.bind((socket.gethostname(), PORT))
OSError: [Errno 98] Address already in use
Traceback (most recent call last):
  File "server.py", line 182, in <module>
    sock.bind((socket.gethostname(), PORT))
OSError: [Errno 98] Address already in use
Traceback (most recent call last):
  File "server.py", line 182, in <module>
    sock.bind((socket.gethostname(), PORT))
OSError: [Errno 98] Address already in use
Traceback (most recent call last):
  File "server.py", line 182, in <module>
    sock.bind((socket.gethostname(), PORT))
OSError: [Errno 98] Address already in use
Traceback (most recent call last):
  File "server.py", line 182, in <module>
    sock.bind((socket.gethostname(), PORT))
OSError: [Errno 98] Address already in use
Traceback (most recent call last):
  File "server.py", line 182, in <module>
    sock.bind((socket.gethostname(), PORT))
OSError: [Errno 98] Address already in use
Traceback (most recent call last):
  File "server.py", line 182, in <module>
    sock.bind((socket.gethostname(), PORT))
OSError: [Errno 98] Address already in use
Traceback (most recent call last):
  File "server.py", line 182, in <module>
    sock.bind((socket.gethostname(), PORT))
OSError: [Errno 98] Address already in use
Traceback (most recent call last):
  File "server.py", line 182, in <module>
    sock.bind((socket.gethostname(), PORT))
OSError: [Errno 98] Address already in use
Traceback (most recent call last):
  File "server.py", line 182, in <module>
    sock.bind((socket.gethostname(), PORT))
OSError: [Errno 98] Address already in use
Traceback (most recent call last):
  File "server.py", line 182, in <module>
    sock.bind((socket.gethostname(), PORT))
OSError: [Errno 98] Address already in use
Traceback (most recent call last):
  File "server.py", line 182, in <module>
    sock.bind((socket.gethostname(), PORT))
OSError: [Errno 98] Address already in use
Traceback (most recent call last):
  File "server.py", line 182, in <module>
    sock.bind((socket.gethostname(), PORT))
OSError: [Errno 98] Address already in use
Traceback (most recent call last):
  File "server.py", line 182, in <module>
    sock.bind((socket.gethostname(), PORT))
OSError: [Errno 98] Address already in use
Traceback (most recent call last):
  File "server.py", line 182, in <module>
    sock.bind((socket.gethostname(), PORT))
OSError: [Errno 98] Address already in use
Traceback (most recent call last):
  File "server.py", line 182, in <module>
    sock.bind((socket.gethostname(), PORT))
OSError: [Errno 98] Address already in use
Traceback (most recent call last):
  File "server.py", line 182, in <module>
    sock.bind((socket.gethostname(), PORT))
OSError: [Errno 98] Address already in use
Traceback (most recent call last):
  File "server.py", line 182, in <module>
    sock.bind((socket.gethostname(), PORT))
OSError: [Errno 98] Address already in use
Traceback (most recent call last):
  File "server.py", line 182, in <module>
    sock.bind((socket.gethostname(), PORT))
OSError: [Errno 98] Address already in use
Traceback (most recent call last):
  File "server.py", line 182, in <module>
    sock.bind((socket.gethostname(), PORT))
OSError: [Errno 98] Address already in use
Traceback (most recent call last):
  File "server.py", line 182, in <module>
    sock.bind((socket.gethostname(), PORT))
OSError: [Errno 98] Address already in use
Traceback (most recent call last):
  File "server.py", line 182, in <module>
    sock.bind((socket.gethostname(), PORT))
OSError: [Errno 98] Address already in use
Traceback (most recent call last):
  File "server.py", line 182, in <module>
    sock.bind((socket.gethostname(), PORT))
OSError: [Errno 98] Address already in use
Traceback (most recent call last):
  File "server.py", line 182, in <module>
    sock.bind((socket.gethostname(), PORT))
OSError: [Errno 98] Address already in use
Traceback (most recent call last):
  File "server.py", line 182, in <module>
    sock.bind((socket.gethostname(), PORT))
OSError: [Errno 98] Address already in use
Traceback (most recent call last):
  File "server.py", line 182, in <module>
    sock.bind((socket.gethostname(), PORT))
OSError: [Errno 98] Address already in use
Traceback (most recent call last):
  File "server.py", line 182, in <module>
    sock.bind((socket.gethostname(), PORT))
OSError: [Errno 98] Address already in use
Traceback (most recent call last):
  File "server.py", line 182, in <module>
    sock.bind((socket.gethostname(), PORT))
OSError: [Errno 98] Address already in use
Traceback (most recent call last):
  File "server.py", line 182, in <module>
    sock.bind((socket.gethostname(), PORT))
OSError: [Errno 98] Address already in use
Traceback (most recent call last):
  File "server.py", line 182, in <module>
    sock.bind((socket.gethostname(), PORT))
OSError: [Errno 98] Address already in use
Traceback (most recent call last):
  File "server.py", line 182, in <module>
    sock.bind((socket.gethostname(), PORT))
OSError: [Errno 98] Address already in use
Traceback (most recent call last):
  File "server.py", line 182, in <module>
    sock.bind((socket.gethostname(), PORT))
OSError: [Errno 98] Address already in use
Traceback (most recent call last):
  File "server.py", line 182, in <module>
    sock.bind((socket.gethostname(), PORT))
OSError: [Errno 98] Address already in use
